<?xml version="1.0"?>
<robot xmlns:xacro="http://www.ros.org/wiki/xacro">
    <xacro:macro name="my_scara_1_0_macro">
        <!-- link list -->
        <link
            name="base">
            <inertial>
            <origin
                xyz="0.029207 -2.9211E-17 0.024645"
                rpy="0 0 0" />
            <mass
                value="1.253" />
            <inertia
                ixx="0.0031229"
                ixy="2.3182E-18"
                ixz="9.8215E-06"
                iyy="0.0059461"
                iyz="1.7197E-18"
                izz="0.0087331" />
            </inertial>
            <visual>
            <origin
                xyz="0 0 0"
                rpy="0 0 0" />
            <geometry>
                <mesh
                filename="package://my_scara_support/meshes/base.STL" />
            </geometry>
            <material
                name="">
                <color
                rgba="0.2 0.4 0.69804 1" />
            </material>
            </visual>
            <collision>
            <origin
                xyz="0 0 0"
                rpy="0 0 0" />
            <geometry>
                <mesh
                filename="package://my_scara_support/meshes/base.STL" />
            </geometry>
            </collision>
        </link>
        <link
            name="coupler_01">
            <inertial>
            <origin
                xyz="-6.93889390390723E-17 0.0072813688212928 -1.52921972221633E-16"
                rpy="0 0 0" />
            <mass
                value="0.139427808957131" />
            <inertia
                ixx="7.74222121811178E-05"
                ixy="-2.15639217181064E-20"
                ixz="1.49941345073938E-23"
                iyy="0.000147610246557407"
                iyz="-4.44282125203463E-20"
                izz="7.74222121811179E-05" />
            </inertial>
            <visual>
            <origin
                xyz="0 0 0"
                rpy="0 0 0" />
            <geometry>
                <mesh lower="-1.5708"
                filename="package://my_scara_support/meshes/coupler_01.STL" />
            </geometry>
            <material
                name="">
                <color
                rgba="0.2 0.4 0.698039215686274 1" />
            </material>
            </visual>
            <collision>
            <origin
                xyz="0 0 0"
                rpy="0 0 0" />
            <geometry>
                <mesh
                filename="package://my_scara_support/meshes/coupler_01.STL" />
            </geometry>
            </collision>
        </link>
        <link
            name="link_01">
            <inertial>
            <origin
                xyz="0.07 0.0250821742955448 1.18862872341622E-17"
                rpy="0 0 0" />
            <mass
                value="0.721333334319361" />
            <inertia
                ixx="0.000655553125789508"
                ixy="3.94662664806033E-18"
                ixz="1.14775790430014E-19"
                iyy="0.00349317611606045"
                iyz="-1.41812187080913E-19"
                izz="0.00305285544145848" />
            </inertial>
            <visual>
            <origin
                xyz="0 0 0"
                rpy="0 0 0" />
            <geometry>
                <mesh
                filename="package://my_scara_support/meshes/link_01.STL" />
            </geometry>
            <material
                name="">
                <color
                rgba="0.2 0.4 0.698039215686274 1" />
            </material>
            </visual>
            <collision>
            <origin
                xyz="0 0 0"
                rpy="0 0 0" />
            <geometry>
                <mesh
                filename="package://my_scara_support/meshes/link_01.STL" />
            </geometry>
            </collision>
        </link>
        <link
            name="coupler_02">
            <inertial>
            <origin
                xyz="-2.77555756156289E-17 0.00728136882129281 -1.53599396082019E-16"
                rpy="0 0 0" />
            <mass
                value="0.139427808957131" />
            <inertia
                ixx="7.74222121811178E-05"
                ixy="-2.15483588593893E-20"
                ixz="-3.26514687756594E-23"
                iyy="0.000147610246557407"
                iyz="-4.43472149629924E-20"
                izz="7.74222121811179E-05" />
            </inertial>
            <visual>
            <origin
                xyz="0 0 0"
                rpy="0 0 0" />
            <geometry>
                <mesh
                filename="package://my_scara_support/meshes/coupler_02.STL" />
            </geometry>
            <material
                name="">
                <color
                rgba="0.2 0.4 0.698039215686274 1" />
            </material>
            </visual>
            <collision>
            <origin
                xyz="0 0 0"
                rpy="0 0 0" />
            <geometry>
                <mesh
                filename="package://my_scara_support/meshes/coupler_02.STL" />
            </geometry>
            </collision>
        </link>
        <link
            name="link_02">
            <inertial>
            <origin
                xyz="0.07 0.0150687991093598 5.47005078454743E-18"
                rpy="0 0 0" />
            <mass
                value="0.553340131043985" />
            <inertia
                ixx="0.000396370069121465"
                ixy="1.75261020780329E-18"
                ixz="-3.11278404261361E-20"
                iyy="0.00248541752718653"
                iyz="-6.55783185714604E-21"
                izz="0.00212974960002337" />
            </inertial>
            <visual>
            <origin
                xyz="0 0 0"
                rpy="0 0 0" />
            <geometry>
                <mesh
                filename="package://my_scara_support/meshes/link_02.STL" />
            </geometry>
            <material
                name="">
                <color
                rgba="0.2 0.4 0.698039215686274 1" />
            </material>
            </visual>
            <collision>
            <origin
                xyz="0 0 0"
                rpy="0 0 0" />
            <geometry>
                <mesh
                filename="package://my_scara_support/meshes/link_02.STL" />
            </geometry>
            </collision>
        </link>
        <link
            name="end_effector">
            <inertial>
            <origin
                xyz="0.100349198973376 0.000353822159549988 6.33217478009659E-12"
                rpy="0 0 0" />
            <mass
                value="0.229959232623262" />
            <inertia
                ixx="8.30636492252994E-05"
                ixy="2.72527313421034E-07"
                ixz="-1.21412680251909E-06"
                iyy="0.00101485834427373"
                iyz="4.63968105288635E-13"
                izz="0.00101637867937415" />
            </inertial>
            <visual>
            <origin
                xyz="0 0 0"
                rpy="0 0 0" />
            <geometry>
                <mesh
                filename="package://my_scara_support/meshes/end_effector.STL" />
            </geometry>
            <material
                name="">
                <color
                rgba="0.686274509803922 0.686274509803922 0.686274509803922 1" />
            </material>
            </visual>
            <collision>
            <origin
                xyz="0 0 0"
                rpy="0 0 0" />
            <geometry>
                <mesh
                filename="package://my_scara_support/meshes/end_effector.STL" />
            </geometry>
            </collision>
        </link>
        <link
            name="motor_02">
            <inertial>
            <origin
                xyz="-1.93256233677813E-17 0.0240903332345709 1.45866755534296E-05"
                rpy="0 0 0" />
            <mass
                value="0.0817024345002187" />
            <inertia
                ixx="1.15959600743729E-05"
                ixy="-2.74505117557949E-22"
                ixz="2.18672896381784E-22"
                iyy="2.2515945470037E-05"
                iyz="1.65216229905401E-09"
                izz="1.16205082096749E-05" />
            </inertial>
            <visual>
            <origin
                xyz="0 0 0"
                rpy="0 0 0" />
            <geometry>
                <mesh
                filename="package://my_scara_support/meshes/motor_02.STL" />
            </geometry>
            <material
                name="">
                <color
                rgba="0.298039215686275 0.298039215686275 0.298039215686275 1" />
            </material>
            </visual>
            <collision>
            <origin
                xyz="0 0 0"
                rpy="0 0 0" />
            <geometry>
                <mesh
                filename="package://my_scara_support/meshes/motor_02.STL" />
            </geometry>
            </collision>
        </link>
        <link
            name="motor_01">
            <inertial>
            <origin
                xyz="0 0 0"
                rpy="0 0 0" />
            <mass
                value="0" />
            <inertia
                ixx="0"
                ixy="0"
                ixz="0"
                iyy="0"
                iyz="0"
                izz="0" />
            </inertial>
            <visual>
            <origin
                xyz="0 0 0"
                rpy="0 0 0" />
            <geometry>
                <mesh
                filename="package://my_scara_support/meshes/motor_01.STL" />
            </geometry>
            <material
                name="">
                <color
                rgba="0.298039215686275 0.298039215686275 0.298039215686275 1" />
            </material>
            </visual>
            <collision>
            <origin
                xyz="0 0 0"
                rpy="0 0 0" />
            <geometry>
                <mesh
                filename="package://my_scara_support/meshes/motor_01.STL" />
            </geometry>
            </collision>
        </link>
        <!-- end of link list -->

        <!-- joint list -->
        <joint
            name="joint_1"
            type="revolute">
            <origin
            xyz="0.075 0 0.05"
            rpy="1.5708 0 0" />
            <parent
            link="base" />
            <child
            link="coupler_01" />
            <axis
            xyz="0 1 0" />
            <limit
            lower="-1.5708"
            upper="+1.5708"
            effort="0"
            velocity="0" />
        </joint>
        <joint
            name="joint_2"
            type="revolute">
            <origin
            xyz="0.14 0.05 0"
            rpy="0 0 0" />
            <parent
            link="link_01" />
            <child
            link="coupler_02" />
            <axis
            xyz="0 1 0" />
            <limit
            lower="-1.5708"
            upper="+1.5708"
            effort="0"
            velocity="0" />
        </joint>
        <joint
            name="weld_motor_01"
            type="fixed">
            <origin
            xyz="0 0 0.0974"
            rpy="-1.5708 0 1.5708" />
            <parent
            link="base" />
            <child
            link="motor_01" />
            <axis
            xyz="0 0 0" />
        </joint>
        <joint
            name="weld_motor_02"
            type="fixed">
            <origin
            xyz="0 0.0974 0"
            rpy="3.14159 1.5708 0" />
            <parent
            link="link_01" />
            <child
            link="motor_02" />
            <axis
            xyz="0 0 0" />
        </joint>
        <joint
            name="weld_01"
            type="fixed">
            <origin
            xyz="0 0.02 0"
            rpy="0 0 0" />
            <parent
            link="coupler_01" />
            <child
            link="link_01" />
            <axis
            xyz="0 0 0" />
        </joint>
        <joint
            name="weld_02"
            type="fixed">
            <origin
            xyz="0 0.02 0"
            rpy="0 0 0" />
            <parent
            link="coupler_02" />
            <child
            link="link_02" />
            <axis
            xyz="0 0 0" />
        </joint>
        <joint
            name="weld_03"
            type="fixed">
            <origin
            xyz="0.14 0.03 0"
            rpy="0 0 1.5708" />
            <parent
            link="link_02" />
            <child
            link="end_effector" />
            <axis
            xyz="0 0 0" />
        </joint>
        <!-- end of joint list -->
    </xacro:macro>
</robot>